Workbook

Sheet Panduan
A1: Spreadsheet HPP & Proyeksi Keuangan — Dapur Online 3×3 m
A2: Pendamping Master Plan Dapur Online. Semua angka adalah estimasi 2026; ganti dengan harga di kota kamu.
A4: Cara pakai
A5: 1. Asumsi | B5: Atur komisi aplikasi, promo, hari buka, gaji, dan biaya tetap.
A6: 2. Rincian HPP | B6: Ubah qty dan harga per satuan bahan setiap menu (teks biru). HPP terhitung otomatis.
A7: 3. Ringkasan HPP | B7: Ubah harga jual dan komposisi penjualan (mix %). Untung per porsi & per order terhitung otomatis.
A8: 4. Modal Awal | B8: Ubah daftar alat dan biaya persiapan. Dana cadangan dihitung dari biaya tetap bulan 1.
A9: 5. Proyeksi 12 Bulan | B9: Ubah target order/hari, jumlah helper, dan budget iklan per bulan.
A11: Kode warna
A12: Teks biru | B12: Input — boleh diubah
A13: Teks hitam | B13: Rumus — jangan diubah
A14: Teks hijau | B14: Mengambil angka dari sheet lain
A15: Latar kuning | B15: Asumsi kunci yang paling berpengaruh ke hasil
A17: Catatan | B17: Komisi aplikasi ±20% adalah perkiraan umum GoFood/GrabFood/ShopeeFood; cek angka terbaru di aplikasi masing-masing.
B18: Sewa dihitung sebagai biaya bulanan. Kalau pemilik minta bayar 6–12 bulan di muka, siapkan dari dana cadangan.

Sheet Asumsi
A1: Asumsi Utama
A2: Teks biru = input. Ubah di sini, semua sheet ikut berubah.
A3: Asumsi | B3: Nilai | C3: Keterangan
A4: Komisi aplikasi ojol | B4: 0.2 | C4: Perkiraan ±20% dari harga menu (cek tiap aplikasi)
A5: Rata-rata biaya promo/diskon per order | B5: 1000 | C5: Subsidi promo yang ditanggung merchant
A6: Hari buka per bulan | B6: 30 | C6: Buka setiap hari
A7: Gaji 1 helper per bulan | B7: 2500000 | C7: Sesuaikan dengan UMR/kebiasaan setempat
A8: Gaji owner per bulan | B8: 0 | C8: Isi kalau owner mau digaji dari usaha
A9: % order yang menambah minuman | B9: 0.35 | C9: Upselling minuman
A10: % order yang menambah lauk/sambal | B10: 0.25 | C10: Upselling add-on
A11: Dana cadangan (x biaya tetap bulan 1) | B11: 2 | C11: Untuk menutup biaya saat order masih sepi
A13: Biaya tetap bulanan (di luar gaji helper & iklan)
A14: Pos biaya | B14: Rp / bulan | C14: Keterangan
A15: Sewa kontrakan | B15: 800000 | C15: Estimasi kontrakan 3×3 m
A16: Listrik & air | B16: 500000 | C16: Estimasi
A17: Internet & pulsa | B17: 200000 | C17: Estimasi
A18: Kebersihan & perawatan alat | B18: 300000 | C18: Estimasi
A19: Transport belanja & lain-lain | B19: 400000 | C19: Estimasi
A20: Total | B20: =SUM(B15:B19) -> 2200000
A22: Gas & listrik untuk memasak sudah dialokasikan per porsi di HPP, jadi tidak dihitung lagi di sini.

Sheet Rincian HPP
A1: Rincian HPP per Menu
A2: Ubah qty dan harga per satuan (biru). Biaya = Qty × Harga per satuan.
A4: Nasi Bakar Ayam Suwir Kemangi · Nasi Bakar
A5: Komponen | B5: Qty | C5: Satuan | D5: Harga / satuan | E5: Biaya
A6: Beras | B6: 0.08 | C6: kg | D6: 14000 | E6: =B6*D6 -> 1120
A7: Santan & bumbu nasi gurih | B7: 1 | C7: porsi | D7: 880 | E7: =B7*D7 -> 880
A8: Ayam suwir bumbu | B8: 0.05 | C8: kg | D8: 60000 | E8: =B8*D8 -> 3000
A9: Kemangi, cabai, bumbu | B9: 1 | C9: porsi | D9: 1500 | E9: =B9*D9 -> 1500
A10: Daun pisang + lidi | B10: 1 | C10: bungkus | D10: 500 | E10: =B10*D10 -> 500
A11: Kemasan (box, sendok, stiker) | B11: 1 | C11: set | D11: 1500 | E11: =B11*D11 -> 1500
A12: Gas & listrik (alokasi) | B12: 1 | C12: porsi | D12: 500 | E12: =B12*D12 -> 500
A13: HPP per porsi | E13: =SUM(E6:E12) -> 9000
A15: Nasi Bakar Tongkol Pedas · Nasi Bakar
A16: Komponen | B16: Qty | C16: Satuan | D16: Harga / satuan | E16: Biaya
A17: Beras | B17: 0.08 | C17: kg | D17: 14000 | E17: =B17*D17 -> 1120
A18: Santan & bumbu nasi gurih | B18: 1 | C18: porsi | D18: 880 | E18: =B18*D18 -> 880
A19: Tongkol suwir bumbu | B19: 0.05 | C19: kg | D19: 50000 | E19: =B19*D19 -> 2500
A20: Kemangi, cabai, bumbu | B20: 1 | C20: porsi | D20: 1500 | E20: =B20*D20 -> 1500
A21: Daun pisang + lidi | B21: 1 | C21: bungkus | D21: 500 | E21: =B21*D21 -> 500
A22: Kemasan (box, sendok, stiker) | B22: 1 | C22: set | D22: 1500 | E22: =B22*D22 -> 1500
A23: Gas & listrik (alokasi) | B23: 1 | C23: porsi | D23: 500 | E23: =B23*D23 -> 500
A24: HPP per porsi | E24: =SUM(E17:E23) -> 8500
A26: Nasi Bakar Cumi Asin · Nasi Bakar
A27: Komponen | B27: Qty | C27: Satuan | D27: Harga / satuan | E27: Biaya
A28: Beras | B28: 0.08 | C28: kg | D28: 14000 | E28: =B28*D28 -> 1120
A29: Santan & bumbu nasi gurih | B29: 1 | C29: porsi | D29: 880 | E29: =B29*D29 -> 880
A30: Cumi asin | B30: 0.04 | C30: kg | D30: 90000 | E30: =B30*D30 -> 3600
A31: Kemangi, cabai, bumbu | B31: 1 | C31: porsi | D31: 1500 | E31: =B31*D31 -> 1500
A32: Daun pisang + lidi | B32: 1 | C32: bungkus | D32: 500 | E32: =B32*D32 -> 500
A33: Kemasan (box, sendok, stiker) | B33: 1 | C33: set | D33: 1500 | E33: =B33*D33 -> 1500
A34: Gas & listrik (alokasi) | B34: 1 | C34: porsi | D34: 500 | E34: =B34*D34 -> 500
A35: HPP per porsi | E35: =SUM(E28:E34) -> 9600
A37: Nasi Bakar Teri Pete · Nasi Bakar
A38: Komponen | B38: Qty | C38: Satuan | D38: Harga / satuan | E38: Biaya
A39: Beras | B39: 0.08 | C39: kg | D39: 14000 | E39: =B39*D39 -> 1120
A40: Santan & bumbu nasi gurih | B40: 1 | C40: porsi | D40: 880 | E40: =B40*D40 -> 880
A41: Teri medan | B41: 0.03 | C41: kg | D41: 100000 | E41: =B41*D41 -> 3000
A42: Pete | B42: 1 | C42: papan kecil | D42: 1000 | E42: =B42*D42 -> 1000
A43: Kemangi, cabai, bumbu | B43: 1 | C43: porsi | D43: 1500 | E43: =B43*D43 -> 1500
A44: Daun pisang + lidi | B44: 1 | C44: bungkus | D44: 500 | E44: =B44*D44 -> 500
...

Sheet Ringkasan HPP
A1: Ringkasan HPP, Harga Jual & Untung per Porsi
A2: Harga jual dan mix % (biru) bisa diubah. Mix % hanya untuk menu utama dan totalnya harus 100%.
A3: Menu | B3: Kategori | C3: Harga jual (aplikasi) | D3: HPP | E3: Komisi aplikasi | F3: Untung per porsi | G3: Food cost % | H3: Mix penjualan %
A4: Nasi Bakar Ayam Suwir Kemangi | B4: Nasi Bakar | C4: 22000 | D4: ='Rincian HPP'!$E$13 -> 9000 | E4: =C4*Asumsi!$B$4 -> 4400 | F4: =C4-E4-D4 -> 8600 | G4: =IF(C4=0,0,D4/C4) -> 0.40909091 | H4: 0.18
A5: Nasi Bakar Tongkol Pedas | B5: Nasi Bakar | C5: 21000 | D5: ='Rincian HPP'!$E$24 -> 8500 | E5: =C5*Asumsi!$B$4 -> 4200 | F5: =C5-E5-D5 -> 8300 | G5: =IF(C5=0,0,D5/C5) -> 0.4047619 | H5: 0.1
A6: Nasi Bakar Cumi Asin | B6: Nasi Bakar | C6: 23000 | D6: ='Rincian HPP'!$E$35 -> 9600 | E6: =C6*Asumsi!$B$4 -> 4600 | F6: =C6-E6-D6 -> 8800 | G6: =IF(C6=0,0,D6/C6) -> 0.4173913 | H6: 0.07
A7: Nasi Bakar Teri Pete | B7: Nasi Bakar | C7: 23000 | D7: ='Rincian HPP'!$E$47 -> 10000 | E7: =C7*Asumsi!$B$4 -> 4600 | F7: =C7-E7-D7 -> 8400 | G7: =IF(C7=0,0,D7/C7) -> 0.43478261 | H7: 0.05
A8: Paket Ayam Bakar Kecap | B8: Ayam | C8: 38000 | D8: ='Rincian HPP'!$E$57 -> 19200 | E8: =C8*Asumsi!$B$4 -> 7600 | F8: =C8-E8-D8 -> 11200 | G8: =IF(C8=0,0,D8/C8) -> 0.50526316 | H8: 0.25
A9: Paket Ayam Bakar Madu Pedas | B9: Ayam | C9: 39000 | D9: ='Rincian HPP'!$E$67 -> 20000 | E9: =C9*Asumsi!$B$4 -> 7800 | F9: =C9-E9-D9 -> 11200 | G9: =IF(C9=0,0,D9/C9) -> 0.51282051 | H9: 0.15
A10: Paket Ayam Bakar Taliwang | B10: Ayam | C10: 39000 | D10: ='Rincian HPP'!$E$77 -> 19700 | E10: =C10*Asumsi!$B$4 -> 7800 | F10: =C10-E10-D10 -> 11500 | G10: =IF(C10=0,0,D10/C10) -> 0.50512821 | H10: 0.08
A11: Paket Ayam Goreng Bumbu Kuning | B11: Ayam | C11: 37000 | D11: ='Rincian HPP'!$E$88 -> 19600 | E11: =C11*Asumsi!$B$4 -> 7400 | F11: =C11-E11-D11 -> 10000 | G11: =IF(C11=0,0,D11/C11) -> 0.52972973 | H11: 0.12
A12: Tahu Tempe Bacem Bakar | B12: Tambahan | C12: 8000 | D12: ='Rincian HPP'!$E$96 -> 3100 | E12: =C12*Asumsi!$B$4 -> 1600 | F12: =C12-E12-D12 -> 3300 | G12: =IF(C12=0,0,D12/C12) -> 0.3875 | H12: add-on
A13: Telur Balado | B13: Tambahan | C13: 8000 | D13: ='Rincian HPP'!$E$103 -> 3300 | E13: =C13*Asumsi!$B$4 -> 1600 | F13: =C13-E13-D13 -> 3100 | G13: =IF(C13=0,0,D13/C13) -> 0.4125 | H13: add-on
A14: Ekstra Sambal | B14: Tambahan | C14: 5000 | D14: ='Rincian HPP'!$E$109 -> 1300 | E14: =C14*Asumsi!$B$4 -> 1000 | F14: =C14-E14-D14 -> 2700 | G14: =IF(C14=0,0,D14/C14) -> 0.26 | H14: add-on
A15: Es Teh Manis (botol) | B15: Minuman | C15: 8000 | D15: ='Rincian HPP'!$E$115 -> 2500 | E15: =C15*Asumsi!$B$4 -> 1600 | F15: =C15-E15-D15 -> 3900 | G15: =IF(C15=0,0,D15/C15) -> 0.3125 | H15: add-on
A16: Es Jeruk (botol) | B16: Minuman | C16: 10000 | D16: ='Rincian HPP'!$E$122 -> 4500 | E16: =C16*Asumsi!$B$4 -> 2000 | F16: =C16-E16-D16 -> 3500 | G16: =IF(C16=0,0,D16/C16) -> 0.45 | H16: add-on
A17: Total mix menu utama (harus 100%) | H17: =SUM(H4:H16) -> 1
A19: Rata-rata per order
A20: Nilai order rata-rata (AOV, harga aplikasi) | B20: =SUMPRODUCT($H$4:$H$16,$C$4:$C$16)+Asumsi!$B$9*AVERAGEIF($B$4:$B$16,"Minuman",$C$4:$C$16)+Asumsi!$B$10*AVERAGEIF($B$4:$B$16,"Tambahan",$C$4:$C$16) -> 36630
A21: HPP rata-rata per order | B21: =SUMPRODUCT($H$4:$H$16,$D$4:$D$16)+Asumsi!$B$9*AVERAGEIF($B$4:$B$16,"Minuman",$D$4:$D$16)+Asumsi!$B$10*AVERAGEIF($B$4:$B$16,"Tambahan",$D$4:$D$16) -> 17236.667
A22: Komisi aplikasi per order | B22: =B20*Asumsi!$B$4 -> 7326
A23: Promo/diskon per order | B23: =Asumsi!$B$5 -> 1000
A24: Untung kotor rata-rata per order | B24: =B20-B21-B22-B23 -> 11067.333

Sheet Modal Awal
A1: Modal Awal
A2: Qty dan harga (biru) bisa diubah. Beli alat bekas bisa hemat 30–50%.
A3: Kategori | B3: Item | C3: Qty | D3: Harga satuan | E3: Total
A4: Peralatan | B4: Kompor 2 tungku tekanan tinggi + regulator & selang | C4: 1 | D4: 800000 | E4: =C4*D4 -> 800000
A5: Peralatan | B5: Panggangan gas / griddle besi / grill pan | C5: 2 | D5: 350000 | E5: =C5*D5 -> 700000
A6: Peralatan | B6: Rice cooker kapasitas besar | C6: 1 | D6: 800000 | E6: =C6*D6 -> 800000
A7: Peralatan | B7: Chest freezer ±100 L | C7: 1 | D7: 2500000 | E7: =C7*D7 -> 2500000
A8: Peralatan | B8: Meja kerja stainless (rak bawah) | C8: 2 | D8: 750000 | E8: =C8*D8 -> 1500000
A9: Peralatan | B9: Rak susun / ambalan dinding | C9: 1 | D9: 800000 | E9: =C9*D9 -> 800000
A10: Peralatan | B10: Bak cuci + keran | C10: 1 | D10: 600000 | E10: =C10*D10 -> 600000
A11: Peralatan | B11: Exhaust fan + pemasangan | C11: 2 | D11: 250000 | E11: =C11*D11 -> 500000
A12: Peralatan | B12: Panci, wajan, spatula, pisau, talenan, baskom | C12: 1 | D12: 1500000 | E12: =C12*D12 -> 1500000
A13: Peralatan | B13: Blender / chopper bumbu | C13: 1 | D13: 400000 | E13: =C13*D13 -> 400000
A14: Peralatan | B14: Timbangan digital | C14: 1 | D14: 150000 | E14: =C14*D14 -> 150000
A15: Peralatan | B15: Wadah penyimpanan food grade | C15: 1 | D15: 500000 | E15: =C15*D15 -> 500000
... A24: Persiapan | B24: Promo & iklan peluncuran | C24: 1 | D24: 2000000 | E24: =C24*D24 -> 2000000
B26: Subtotal peralatan | E26: =SUMIF(A4:A24,"Peralatan",E4:E24) -> 12100000
B27: Subtotal persiapan | E27: =SUMIF(A4:A24,"Persiapan",E4:E24) -> 10000000
B28: Dana cadangan operasional | E28: =Asumsi!$B$11*'Proyeksi 12 Bulan'!$B$24 -> 11400000
B29: TOTAL MODAL AWAL | E29: =SUM(E26:E28) -> 33500000
B31: Dana cadangan = jumlah bulan cadangan (sheet Asumsi) × total biaya tetap bulan 1 (sheet Proyeksi).

Sheet Proyeksi 12 Bulan
A1: Proyeksi Laba Rugi 12 Bulan (skenario moderat)
A2: Ubah order/hari, jumlah helper, iklan, dan admin per bulan (biru). Baris lain dihitung otomatis.
A3: Keterangan | B3: Bulan 1 | C3: Bulan 2 | D3: Bulan 3 | E3: Bulan 4 | F3: Bulan 5 | G3: Bulan 6 | H3: Bulan 7 | I3: Bulan 8 | J3: Bulan 9 | K3: Bulan 10 | L3: Bulan 11 | M3: Bulan 12 | N3: Total 12 bln
A4: Target order per hari | B4: 15 | C4: 22 | D4: 30 | E4: 36 | F4: 42 | G4: 50 | H4: 60 | I4: 66 | J4: 72 | K4: 78 | L4: 84 | M4: 90
A5: Hari buka | B5: =Asumsi!$B$6 -> 30 | C5: =Asumsi!$B$6 -> 30 | D5: =Asumsi!$B$6 -> 30 | E5: =Asumsi!$B$6 -> 30 | F5: =Asumsi!$B$6 -> 30 | G5: =Asumsi!$B$6 -> 30 | H5: =Asumsi!$B$6 -> 30 | I5: =Asumsi!$B$6 -> 30 | ... M5: =Asumsi!$B$6 -> 30
A6: Total order per bulan | B6: =B4*B5 -> 450 | C6: =C4*C5 -> 660 | D6: =D4*D5 -> 900 | E6: =E4*E5 -> 1080 | F6: =F4*F5 -> 1260 | G6: =G4*G5 -> 1500 | H6: =H4*H5 -> 1800 | I6: =I4*I5 -> 1980 | ... M6: =M4*M5 -> 2700 | N6: =SUM(B6:M6) -> 19350
A7: Omzet (harga di aplikasi) | B7: =B6*'Ringkasan HPP'!$B$20 -> 16483500 | C7: =C6*'Ringkasan HPP'!$B$20 -> 24175800 | D7: =D6*'Ringkasan HPP'!$B$20 -> 32967000 | E7: =E6*'Ringkasan HPP'!$B$20 -> 39560400 | F7: =F6*'Ringkasan HPP'!$B$20 -> 46153800 | G7: =G6*'Ringkasan HPP'!$B$20 -> 54945000 | H7: =H6*'Ringkasan HPP'!$B$20 -> 65934000 | I7: =I6*'Ringkasan HPP'!$B$20 -> 72527400 | ... M7: =M6*'Ringkasan HPP'!$B$20 -> 98901000 | N7: =SUM(B7:M7) -> 708790500
A8: (−) Komisi aplikasi | B8: =B7*Asumsi!$B$4 -> 3296700 | C8: =C7*Asumsi!$B$4 -> 4835160 | D8: =D7*Asumsi!$B$4 -> 6593400 | E8: =E7*Asumsi!$B$4 -> 7912080 | F8: =F7*Asumsi!$B$4 -> 9230760 | G8: =G7*Asumsi!$B$4 -> 10989000 | H8: =H7*Asumsi!$B$4 -> 13186800 | I8: =I7*Asumsi!$B$4 -> 14505480 | ... M8: =M7*Asumsi!$B$4 -> 19780200 | N8: =SUM(B8:M8) -> 141758100
A9: (−) HPP bahan & kemasan | B9: =B6*'Ringkasan HPP'!$B$21 -> 7756500 | C9: =C6*'Ringkasan HPP'!$B$21 -> 11376200 | D9: =D6*'Ringkasan HPP'!$B$21 -> 15513000 | E9: =E6*'Ringkasan HPP'!$B$21 -> 18615600 | F9: =F6*'Ringkasan HPP'!$B$21 -> 21718200 | G9: =G6*'Ringkasan HPP'!$B$21 -> 25855000 | H9: =H6*'Ringkasan HPP'!$B$21 -> 31026000 | I9: =I6*'Ringkasan HPP'!$B$21 -> 34128600 | ... M9: =M6*'Ringkasan HPP'!$B$21 -> 46539000 | N9: =SUM(B9:M9) -> 333529500
A10: (−) Promo/diskon | B10: =B6*Asumsi!$B$5 -> 450000 | C10: =C6*Asumsi!$B$5 -> 660000 | D10: =D6*Asumsi!$B$5 -> 900000 | E10: =E6*Asumsi!$B$5 -> 1080000 | F10: =F6*Asumsi!$B$5 -> 1260000 | G10: =G6*Asumsi!$B$5 -> 1500000 | H10: =H6*Asumsi!$B$5 -> 1800000 | I10: =I6*Asumsi!$B$5 -> 1980000 | ... M10: =M6*Asumsi!$B$5 -> 2700000 | N10: =SUM(B10:M10) -> 19350000
A11: Untung kotor | B11: =B7-B8-B9-B10 -> 4980300 | C11: =C7-C8-C9-C10 -> 7304440 | D11: =D7-D8-D9-D10 -> 9960600 | E11: =E7-E8-E9-E10 -> 11952720 | F11: =F7-F8-F9-F10 -> 13944840 | G11: =G7-G8-G9-G10 -> 16601000 | H11: =H7-H8-H9-H10 -> 19921200 | I11: =I7-I8-I9-I10 -> 21913320 | ... M11: =M7-M8-M9-M10 -> 29881800 | N11: =SUM(B11:M11) -> 214152900
A13: Biaya tetap
A14: Sewa kontrakan | B14: =Asumsi!$B$15 -> 800000 | C14: =Asumsi!$B$15 -> 800000 | D14: =Asumsi!$B$15 -> 800000 | E14: =Asumsi!$B$15 -> 800000 | F14: =Asumsi!$B$15 -> 800000 | G14: =Asumsi!$B$15 -> 800000 | H14: =Asumsi!$B$15 -> 800000 | I14: =Asumsi!$B$15 -> 800000 | ... M14: =Asumsi!$B$15 -> 800000 | N14: =SUM(B14:M14) -> 9600000
A15: Listrik & air | B15: =Asumsi!$B$16 -> 500000 | C15: =Asumsi!$B$16 -> 500000 | D15: =Asumsi!$B$16 -> 500000 | E15: =Asumsi!$B$16 -> 500000 | F15: =Asumsi!$B$16 -> 500000 | G15: =Asumsi!$B$16 -> 500000 | H15: =Asumsi!$B$16 -> 500000 | I15: =Asumsi!$B$16 -> 500000 | ... M15: =Asumsi!$B$16 -> 500000 | N15: =SUM(B15:M15) -> 6000000
A16: Internet & pulsa | B16: =Asumsi!$B$17 -> 200000 | C16: =Asumsi!$B$17 -> 200000 | D16: =Asumsi!$B$17 -> 200000 | E16: =Asumsi!$B$17 -> 200000 | F16: =Asumsi!$B$17 -> 200000 | G16: =Asumsi!$B$17 -> 200000 | H16: =Asumsi!$B$17 -> 200000 | I16: =Asumsi!$B$17 -> 200000 | ... M16: =Asumsi!$B$17 -> 200000 | N16: =SUM(B16:M16) -> 2400000
A17: Kebersihan & perawatan alat | B17: =Asumsi!$B$18 -> 300000 | C17: =Asumsi!$B$18 -> 300000 | D17: =Asumsi!$B$18 -> 300000 | E17: =Asumsi!$B$18 -> 300000 | F17: =Asumsi!$B$18 -> 300000 | G17: =Asumsi!$B$18 -> 300000 | H17: =Asumsi!$B$18 -> 300000 | I17: =Asumsi!$B$18 -> 300000 | ... M17: =Asumsi!$B$18 -> 300000 | N17: =SUM(B17:M17) -> 3600000
A18: Transport belanja & lain-lain | B18: =Asumsi!$B$19 -> 400000 | C18: =Asumsi!$B$19 -> 400000 | D18: =Asumsi!$B$19 -> 400000 | E18: =Asumsi!$B$19 -> 400000 | F18: =Asumsi!$B$19 -> 400000 | G18: =Asumsi!$B$19 -> 400000 | H18: =Asumsi!$B$19 -> 400000 | I18: =Asumsi!$B$19 -> 400000 | ... M18: =Asumsi!$B$19 -> 400000 | N18: =SUM(B18:M18) -> 4800000
A19: Jumlah helper | B19: 1 | C19: 1 | D19: 1 | E19: 1 | F19: 1 | G19: 2 | H19: 2 | I19: 2 | J19: 2 | K19: 2 | L19: 2 | M19: 2
A20: Gaji helper | B20: =B19*Asumsi!$B$7 -> 2500000 | C20: =C19*Asumsi!$B$7 -> 2500000 | D20: =D19*Asumsi!$B$7 -> 2500000 | E20: =E19*Asumsi!$B$7 -> 2500000 | F20: =F19*Asumsi!$B$7 -> 2500000 | G20: =G19*Asumsi!$B$7 -> 5000000 | H20: =H19*Asumsi!$B$7 -> 5000000 | I20: =I19*Asumsi!$B$7 -> 5000000 | ... M20: =M19*Asumsi!$B$7 -> 5000000 | N20: =SUM(B20:M20) -> 47500000
A21: Iklan & promo berbayar | B21: 1000000 | C21: 1000000 | D21: 1000000 | E21: 1000000 | F21: 1000000 | G21: 1500000 | H21: 1500000 | I21: 1500000 | J21: 1500000 | K21: 2000000 | L21: 2000000 | M21: 2000000 | N21: =SUM(B21:M21) -> 17000000
A22: Admin/marketing paruh waktu | B22: 0 | C22: 0 | D22: 0 | E22: 0 | F22: 0 | G22: 0 | H22: 0 | I22: 0 | J22: 0 | K22: 1000000 | L22: 1000000 | M22: 1000000 | N22: =SUM(B22:M22) -> 3000000
A23: Gaji owner | B23: =Asumsi!$B$8 -> 0 | C23: =Asumsi!$B$8 -> 0 | D23: =Asumsi!$B$8 -> 0 | E23: =Asumsi!$B$8 -> 0 | F23: =Asumsi!$B$8 -> 0 | G23: =Asumsi!$B$8 -> 0 | H23: =Asumsi!$B$8 -> 0 | I23: =Asumsi!$B$8 -> 0 | ... M23: =Asumsi!$B$8 -> 0 | N23: =SUM(B23:M23) -> 0
A24: Total biaya tetap | B24: =SUM(B14:B18)+SUM(B20:B23) -> 5700000 | C24: =SUM(C14:C18)+SUM(C20:C23) -> 5700000 | D24: =SUM(D14:D18)+SUM(D20:D23) -> 5700000 | E24: =SUM(E14:E18)+SUM(E20:E23) -> 5700000 | F24: =SUM(F14:F18)+SUM(F20:F23) -> 5700000 | G24: =SUM(G14:G18)+SUM(G20:G23) -> 8700000 | H24: =SUM(H14:H18)+SUM(H20:H23) -> 8700000 | I24: =SUM(I14:I18)+SUM(I20:I23) -> 8700000 | ... M24: =SUM(M14:M18)+SUM(M20:M23) -> 10200000 | N24: =SUM(B24:M24) -> 93900000
A26: LABA BERSIH | B26: =B11-B24 -> -719700 | C26: =C11-C24 -> 1604440 | D26: =D11-D24 -> 4260600 | E26: =E11-E24 -> 6252720 | F26: =F11-F24 -> 8244840 | G26: =G11-G24 -> 7901000 | H26: =H11-H24 -> 11221200 | I26: =I11-I24 -> 13213320 | ... M26: =M11-M24 -> 19681800 | N26: =SUM(B26:M26) -> 120252900
A27: Laba kumulatif (setelah modal awal) | B27: =-'Modal Awal'!$E$29+B26 -> -34219700 | C27: =B27+C26 -> -32615260 | D27: =C27+D26 -> -28354660 | E27: =D27+E26 -> -22101940 | F27: =E27+F26 -> -13857100 | G27: =F27+G26 -> -5956100 | H27: =G27+H26 -> 5265100 | I27: =H27+I26 -> 18478420 | J27: =I27+J26 -> 33683860 | ... M27: =L27+M26 -> 86752900
A28: Margin laba bersih | B28: =IF(B7=0,0,B26/B7) -> -0.043661844 | C28: =IF(C7=0,0,C26/C7) -> 0.066365539 | D28: =IF(D7=0,0,D26/D7) -> 0.12923833 | E28: =IF(E7=0,0,E26/E7) -> 0.15805502 | F28: =IF(F7=0,0,F26/F7) -> 0.17863838 | G28: =IF(G7=0,0,G26/G7) -> 0.14379834 | H28: =IF(H7=0,0,H26/H7) -> 0.17018837 | I28: =IF(I7=0,0,I26/I7) -> 0.18218384 | ... N28: =IF(N7=0,0,N26/N7) -> 0.1696593
A30: Indikator kunci
A31: Modal awal | B31: ='Modal Awal'!$E$29 -> 33500000
A32: Untung kotor rata-rata per order | B32: ='Ringkasan HPP'!$B$24 -> 11067.333
A33: BEP (order per hari, biaya tetap bulan 1) | B33: =IF('Ringkasan HPP'!$B$24<=0,0,B24/'Ringkasan HPP'!$B$24/B5) -> 17.167641
A34: Balik modal di bulan ke- | B34: =IF(COUNTIF(B27:M27,"<0")>=12,"> 12 bulan",COUNTIF(B27:M27,"<0")+1) -> 7
A35: Laba bersih 12 bulan | B35: =N26 -> 120252900
