Workbook

Sheet Ringkasan
A1: LEMBAR KERJA BANGUNAN WARKOP
A2: Tanah 400 m² · struktur kolom baja + rangka atap baja ringan · dinding partisi GRC
A4: Ringkasan | B4: Paket A · Lengkap | C4: Paket B · Hemat | D4: Paket C · Mulai Kecil
A5: Luas bangunan tertutup (m²) | B5: =Volume!C6 | C5: =Volume!D6 | D5: =Volume!E6
A6: Luas teras beratap (m²) | B6: =Volume!C7 | C6: =Volume!D7 | D6: =Volume!E7
A7: Luas lantai beratap total (m²) | B7: =Volume!C8 | C7: =Volume!D8 | D7: =Volume!E8
A8: Luas atap miring (m²) | B8: =Volume!C14 | C8: =Volume!D14 | D8: =Volume!E14
A9: Jumlah kolom baja | B9: =Volume!C17 | C9: =Volume!D17 | D9: =Volume!E17
A10: TOTAL BIAYA BANGUNAN | B10: =RAB!F93 | C10: =RAB!H93 | D10: =RAB!J93
A11: Biaya per m² lantai beratap | B11: =RAB!F94 | C11: =RAB!H94 | D11: =RAB!J94
A12: Modal yang tersedia (ubah bila perlu) | B12: 50000000 | C12: 50000000 | D12: 50000000
A13: Kekurangan dana (bangunan saja) | B13: =MAX(0,B10-B12) | C13: =MAX(0,C10-C12) | D13: =MAX(0,D10-D12)
A15: RINCIAN PER DIVISI
A16: Divisi | B16: Paket A · Lengkap | C16: Paket B · Hemat | D16: Paket C · Mulai Kecil
A17: I. Pekerjaan Persiapan | B17: =RAB!F10 | C17: =RAB!H10 | D17: =RAB!J10
A18: II. Pondasi & Sloof | B18: =RAB!F15 | C18: =RAB!H15 | D18: =RAB!J15
A19: III. Lantai | B19: =RAB!F24 | C19: =RAB!H24 | D19: =RAB!J24
A20: IV. Struktur Baja (Kolom & Ring Balk) | B20: =RAB!F32 | C20: =RAB!H32 | D20: =RAB!J32
A21: V. Atap | B21: =RAB!F41 | C21: =RAB!H41 | D21: =RAB!J41
A22: VI. Dinding Partisi | B22: =RAB!F51 | C22: =RAB!H51 | D22: =RAB!J51
A23: VII. Plafon | B23: =RAB!F55 | C23: =RAB!H55 | D23: =RAB!J55
A24: VIII. Pintu & Jendela | B24: =RAB!F63 | C24: =RAB!H63 | D24: =RAB!J63
A25: IX. Air & Sanitasi | B25: =RAB!F74 | C25: =RAB!H74 | D25: =RAB!J74
A26: X. Listrik | B26: =RAB!F82 | C26: =RAB!H82 | D26: =RAB!J82
A27: XI. Perizinan & Lain-Lain | B27: =RAB!F89 | C27: =RAB!H89 | D27: =RAB!J89
A28: Kontingensi | B28: =RAB!F92 | C28: =RAB!H92 | D28: =RAB!J92
A30: CARA PAKAI
A31: 1. Sheet Input: ubah ukuran tanah, bangunan, jumlah pintu/titik listrik, dll. (sel kuning).
A32: 2. Sheet RAB: ganti harga satuan (kolom D) dengan harga dari tukang/toko di daerahmu.
A33: 3. Sheet Material: daftar belanja untuk mengecek penawaran tukang.
A34: 4. Sheet Jadwal: pilih paket, sesuaikan minggu mulai & durasi, isi progres aktual tiap minggu.
A35: 5. Sheet Checklist QC: dipakai saat mengawasi tukang di lapangan.
A37: CATATAN TEKNIS PENTING
A38: • Baja ringan (kanal C75) dipakai untuk RANGKA ATAP. Kolom utama memakai hollow galvanis 100×100 tebal ≥ 2 mm yang dilas ke base plate & angkur.
A39: • Dinding partisi GRC: bagian bawah harus duduk di atas sloof beton (± 10–20 cm di atas tanah) supaya tidak lapuk terkena air.
A40: • Toilet & area basah dapur memakai bata ringan + waterproofing, bukan papan.
A41: • Bangunan semi permanen tetap perlu PBG. Minta drafter/insinyur memeriksa gambar & ukuran struktur, terutama jika jarak kolom > 4 m atau daerah berangin kencang.
A42: • Semua harga adalah perkiraan 2026 kota pinggiran (material + upah borongan). Minta minimal 3 penawaran.

Sheet Input
A1: INPUT UKURAN & SPESIFIKASI (sel kuning boleh diubah)
A2: Satu kolom = satu pilihan bangunan. Ubah angka sesuai tanah dan kebutuhanmu; semua sheet lain ikut berubah.
A4: Parameter | B4: Satuan | C4: Paket A · Lengkap | D4: Paket B · Hemat | E4: Paket C · Mulai Kecil | F4: Keterangan
A5: TANAH
A6: Lebar tanah (sisi jalan) | B6: m | C6: 20 | D6: 20 | E6: 20 | F6: Tanah 400 m² diasumsikan 20 × 20 m
A7: Panjang tanah (ke belakang) | B7: m | C7: 20 | D7: 20 | E7: 20
A8: BANGUNAN TERTUTUP (dinding partisi)
A9: Lebar bangunan tertutup | B9: m | C9: 8 | D9: 6 | E9: 4 | F9: Sejajar jalan; teras beratap memakai lebar yang sama
A10: Panjang bangunan tertutup | B10: m | C10: 10 | D10: 8 | E10: 5 | F10: Bar, area duduk dalam, dapur, toilet, gudang
A11: Tinggi dinding | B11: m | C11: 3.2 | D11: 3 | E11: 3 | F11: Dari lantai ke ring balk
A12: Panjang partisi dalam (GRC) | B12: m' | C12: 10 | D12: 6 | E12: 3 | F12: Sekat dapur, gudang, ruang staf
A13: Jumlah toilet | B13: unit | C13: 2 | D13: 1 | E13: 1 | F13: Dinding toilet bata ringan (tahan air)
A14: Panjang dinding toilet bata ringan | B14: m' | C14: 7 | D14: 4 | E14: 4
A15: TERAS BERATAP & ATAP
A16: Kedalaman teras beratap (terbuka) | B16: m | C16: 6 | D16: 8 | E16: 6 | F16: Area nongkrong semi-outdoor di depan bangunan
A17: Overstek / tritisan atap | B17: m | C17: 0.6 | D17: 0.5 | E17: 0.5 | F17: Tiap sisi
A18: Kemiringan atap pelana | B18: ° | C18: 25 | D18: 20 | E18: 15 | F18: Spandek: min. 10–15°
A19: Jarak kolom maksimum | B19: m | C19: 4 | D19: 4 | E19: 4 | F19: Jarak kolom > 4 m perlu hitungan struktur
A20: PINTU, JENDELA, FINISHING
A21: Lebar rolling door depan | B21: m | C21: 4 | D21: 3 | E21: 3
A22: Tinggi rolling door depan | B22: m | C22: 3 | D22: 2.8 | E22: 2.5
A23: Jumlah jendela aluminium 100×120 | B23: unit | C23: 6 | D23: 3 | E23: 1
A24: Jumlah pintu dalam (dapur/gudang) | B24: unit | C24: 2 | D24: 1 | E24: 0
A25: Jumlah pintu belakang/servis | B25: unit | C25: 1 | D25: 1 | E25: 1
A26: Pakai plafon di bangunan tertutup? (1 = ya, 0 = tidak) | B26: 1/0 | C26: 1 | D26: 0 | E26: 0 | F26: Tanpa plafon: rangka atap ekspos + foil
A27: Lantai dalam keramik? (1 = keramik, 0 = floor hardener) | B27: 1/0 | C27: 1 | D27: 0 | E27: 0 | F27: Teras selalu floor hardener
A28: Railing/pagar rendah teras | B28: m' | C28: 10 | D28: 0 | E28: 0
A29: Luas parkir sirtu dipadatkan | B29: m² | C29: 80 | D29: 60 | E29: 30
A30: AIR & LISTRIK
A31: Titik lampu | B31: titik | C31: 20 | D31: 14 | E31: 8
A32: Titik stop kontak | B32: titik | C32: 22 | D32: 14 | E32: 8 | F32: Termasuk colokan meja pelanggan
A33: Titik air (kran, kloset, wastafel, sink) | B33: titik | C33: 8 | D33: 5 | E33: 4
A34: Wastafel pelanggan | B34: unit | C34: 2 | D34: 1 | E34: 1
A35: Daya PLN pasang baru | B35: VA | C35: 4400 | D35: 3500 | E35: 2200
A36: Sumur bor + pompa? (1 = ya, 0 = PDAM/sudah ada) | B36: 1/0 | C36: 1 | D36: 1 | E36: 1
A37: LAIN-LAIN
A38: Urus PBG & gambar kerja? (1 = ya) | B38: 1/0 | C38: 1 | D38: 1 | E38: 1 | F38: Persetujuan Bangunan Gedung, wajib sebelum membangun
A39: Dana tak terduga (kontingensi) | B39: % | C39: 0.1 | D39: 0.1 | E39: 0.1 | F39: Disarankan 10%
A40: Faktor sisa/potongan material | B40: % | C40: 0.07 | D40: 0.07 | E40: 0.07 | F40: Untuk daftar belanja

Sheet Volume
A1: PERHITUNGAN VOLUME (otomatis dari sheet Input)
A3: Uraian | B3: Satuan | C3: Paket A · Lengkap | D3: Paket B · Hemat | E3: Paket C · Mulai Kecil | F3: Cara hitung
A4: LUAS
A5: Luas tanah | B5: m² | C5: =Input!$C$6*Input!$C$7 | D5: =Input!$D$6*Input!$D$7 | E5: =Input!$E$6*Input!$E$7 | F5: lebar × panjang tanah
A6: Luas bangunan tertutup | B6: m² | C6: =Input!$C$9*Input!$C$10 | D6: =Input!$D$9*Input!$D$10 | E6: =Input!$E$9*Input!$E$10
A7: Luas teras beratap | B7: m² | C7: =Input!$C$9*Input!$C$16 | D7: =Input!$D$9*Input!$D$16 | E7: =Input!$E$9*Input!$E$16 | F7: lebar bangunan × kedalaman teras
A8: Luas lantai beratap total | B8: m² | C8: =$C$6+$C$7 | D8: =$D$6+$D$7 | E8: =$E$6+$E$7
A9: Koefisien dasar bangunan (KDB) | B9: % | C9: =$C$8/$C$5 | D9: =$D$8/$D$5 | E9: =$E$8/$E$5 | F9: Cek batas KDB di Perda/RTRW setempat
A10: ATAP & STRUKTUR
A11: Panjang atap (proyeksi) | B11: m | C11: =Input!$C$10+Input!$C$16+2*Input!$C$17 | D11: =Input!$D$10+Input!$D$16+2*Input!$D$17 | E11: =Input!$E$10+Input!$E$16+2*Input!$E$17
A12: Lebar atap (proyeksi) | B12: m | C12: =Input!$C$9+2*Input!$C$17 | D12: =Input!$D$9+2*Input!$D$17 | E12: =Input!$E$9+2*Input!$E$17
A13: Luas proyeksi atap | B13: m² | C13: =$C$11*$C$12 | D13: =$D$11*$D$12 | E13: =$E$11*$E$12
A14: Luas bidang atap miring | B14: m² | C14: =$C$13/COS(RADIANS(Input!$C$18)) | D14: =$D$13/COS(RADIANS(Input!$D$18)) | E14: =$E$13/COS(RADIANS(Input!$E$18)) | F14: proyeksi ÷ cos(kemiringan)
A15: Jumlah baris kolom arah lebar | B15: baris | C15: =ROUNDUP(Input!$C$9/Input!$C$19,0)+1 | D15: =ROUNDUP(Input!$D$9/Input!$D$19,0)+1 | E15: =ROUNDUP(Input!$E$9/Input!$E$19,0)+1
A16: Jumlah baris kolom arah panjang | B16: baris | C16: =ROUNDUP((Input!$C$10+Input!$C$16)/Input!$C$19,0)+1 | D16: =ROUNDUP((Input!$D$10+Input!$D$16)/Input!$D$19,0)+1 | E16: =ROUNDUP((Input!$E$10+Input!$E$16)/Input!$E$19,0)+1
A17: Jumlah kolom baja | B17: titik | C17: =$C$15*$C$16 | D17: =$D$15*$D$16 | E17: =$E$15*$E$16 | F17: grid kolom
A18: Panjang ring balk | B18: m' | C18: =$C$15*(Input!$C$10+Input!$C$16)+$C$16*Input!$C$9 | D18: =$D$15*(Input!$D$10+Input!$D$16)+$D$16*Input!$D$9 | E18: =$E$15*(Input!$E$10+Input!$E$16)+$E$16*Input!$E$9 | F18: semua garis grid kolom
A19: Batang ring balk hollow 6 m | B19: batang | C19: =ROUNDUP($C$18/6*(1+Input!$C$40),0) | D19: =ROUNDUP($D$18/6*(1+Input!$D$40),0) | E19: =ROUNDUP($E$18/6*(1+Input!$E$40),0)
A20: Panjang nok/bubungan | B20: m' | C20: =$C$11 | D20: =$D$11 | E20: =$E$11
A21: Panjang lisplang | B21: m' | C21: =2*$C$11+2*$C$12/COS(RADIANS(Input!$C$18)) | D21: =2*$D$11+2*$D$12/COS(RADIANS(Input!$D$18)) | E21: =2*$E$11+2*$E$12/COS(RADIANS(Input!$E$18))
A22: Panjang talang | B22: m' | C22: =2*$C$11 | D22: =2*$D$11 | E22: =2*$E$11 | F22: dua sisi tritisan
A23: PONDASI & LANTAI
A24: Keliling bangunan tertutup | B24: m' | C24: =2*(Input!$C$9+Input!$C$10) | D24: =2*(Input!$D$9+Input!$D$10) | E24: =2*(Input!$E$9+Input!$E$10)
A25: Panjang sloof (bawah dinding) | B25: m' | C25: =$C$24+Input!$C$12+Input!$C$14 | D25: =$D$24+Input!$D$12+Input!$D$14 | E25: =$E$24+Input!$E$12+Input!$E$14
A26: Urugan pasir t = 10 cm | B26: m³ | C26: =$C$8*0.1 | D26: =$D$8*0.1 | E26: =$E$8*0.1
A27: Lantai rabat beton t = 8 cm + wiremesh | B27: m² | C27: =$C$8 | D27: =$D$8 | E27: =$E$8
A28: Keramik lantai dalam | B28: m² | C28: =Input!$C$27*$C$6 | D28: =Input!$D$27*$D$6 | E28: =Input!$E$27*$E$6
A29: Floor hardener / acian (teras + dalam bila tanpa keramik) | B29: m² | C29: =$C$7+(1-Input!$C$27)*$C$6 | D29: =$D$7+(1-Input!$D$27)*$D$6 | E29: =$E$7+(1-Input!$E$27)*$E$6
A30: Keramik dinding toilet h = 1,5 m | B30: m² | C30: =Input!$C$13*6*1.5 | D30: =Input!$D$13*6*1.5 | E30: =Input!$E$13*6*1.5 | F30: ± 6 m' keliling per toilet
A31: DINDING
A32: Luas bukaan di dinding luar | B32: m² | C32: =Input!$C$21*Input!$C$22+Input!$C$23*1*1.2+Input!$C$25*0.9*2.1 | D32: =Input!$D$21*Input!$D$22+Input!$D$23*1*1.2+Input!$D$25*0.9*2.1 | E32: =Input!$E$21*Input!$E$22+Input!$E$23*1*1.2+Input!$E$25*0.9*2.1
A33: Dinding luar partisi (bersih) | B33: m² | C33: =$C$24*Input!$C$11-$C$32 | D33: =$D$24*Input!$D$11-$D$32 | E33: =$E$24*Input!$E$11-$E$32 | F33: keliling × tinggi − bukaan
A34: Partisi dalam (bersih) | B34: m² | C34: =Input!$C$12*Input!$C$11-Input!$C$24*0.8*2.1 | D34: =Input!$D$12*Input!$D$11-Input!$D$24*0.8*2.1 | E34: =Input!$E$12*Input!$E$11-Input!$E$24*0.8*2.1
A35: Dinding toilet bata ringan (bersih) | B35: m² | C35: =Input!$C$14*Input!$C$11-Input!$C$13*0.7*2 | D35: =Input!$D$14*Input!$D$11-Input!$D$13*0.7*2 | E35: =Input!$E$14*Input!$E$11-Input!$E$13*0.7*2
A36: Waterproofing toilet (lantai + dinding) | B36: m² | C36: =$C$30+Input!$C$13*2.25 | D36: =$D$30+Input!$D$13*2.25 | E36: =$E$30+Input!$E$13*2.25
A37: Cat interior | B37: m² | C37: =$C$33+2*$C$34+$C$35 | D37: =$D$33+2*$D$34+$D$35 | E37: =$E$33+2*$E$34+$E$35
A38: Cat eksterior | B38: m² | C38: =$C$33 | D38: =$D$33 | E38: =$E$33
A39: Plafon | B39: m² | C39: =Input!$C$26*$C$6 | D39: =Input!$D$26*$D$6 | E39: =Input!$E$26*$E$6
A40: Rolling door | B40: m² | C40: =Input!$C$21*Input!$C$22 | D40: =Input!$D$21*Input!$D$22 | E40: =Input!$E$21*Input!$E$22
A41: UTILITAS
...

Sheet RAB
A1: RENCANA ANGGARAN BIAYA (harga satuan = material + upah, sistem borongan)
A2: Harga satuan adalah perkiraan 2026 untuk kota pinggiran. Minta minimal 3 penawaran tukang/kontraktor, lalu ganti sel kuning kolom D.
A4: No | B4: Uraian pekerjaan | C4: Satuan | D4: Harga satuan | E4: Vol A | F4: Jumlah A | G4: Vol B | H4: Jumlah B | I4: Vol C | J4: Jumlah C | K4: Spesifikasi / catatan
A5: I | B5: PEKERJAAN PERSIAPAN
A6: 1 | B6: Pembersihan & perataan lahan | C6: m² | D6: 5000 | E6: =Volume!$C$5 | F6: =E6*$D6 | G6: =Volume!$D$5 | H6: =G6*$D6 | I6: =Volume!$E$5 | J6: =I6*$D6 | K6: Seluruh tanah
A7: 2 | B7: Pengukuran & bowplank | C7: m' | D7: 15000 | E7: =Volume!$C$42 | F7: =E7*$D7 | G7: =Volume!$D$42 | H7: =G7*$D7 | I7: =Volume!$E$42 | J7: =I7*$D7
A8: 3 | B8: Gudang material & los kerja sementara | C8: ls | D8: 2000000 | E8: =1 | F8: =E8*$D8 | G8: =1 | H8: =G8*$D8 | I8: =1 | J8: =I8*$D8
A9: 4 | B9: Air & listrik kerja | C9: ls | D9: 1500000 | E9: =1 | F9: =E9*$D9 | G9: =1 | H9: =G9*$D9 | I9: =1 | J9: =I9*$D9
B10: Subtotal I | F10: =SUM(F6:F9) | H10: =SUM(H6:H9) | J10: =SUM(J6:J9)
A12: II | B12: PONDASI & SLOOF
A13: 1 | B13: Pondasi telapak/umpak beton bertulang 60×60 + pedestal 20×20 h 60 cm + angkur | C13: titik | D13: 750000 | E13: =Volume!$C$17 | F13: =E13*$D13 | G13: =Volume!$D$17 | H13: =G13*$D13 | I13: =Volume!$E$17 | J13: =I13*$D13 | K13: Beton K-225, besi D10–D12
A14: 2 | B14: Sloof beton 15×20 cm bawah dinding | C14: m' | D14: 230000 | E14: =Volume!$C$25 | F14: =E14*$D14 | G14: =Volume!$D$25 | H14: =G14*$D14 | I14: =Volume!$E$25 | J14: =I14*$D14 | K14: 4 D10, sengkang Ø8-15
B15: Subtotal II | F15: =SUM(F13:F14) | H15: =SUM(H13:H14) | J15: =SUM(J13:J14)
A17: III | B17: LANTAI
A18: 1 | B18: Urugan pasir bawah lantai t = 10 cm | C18: m³ | D18: 300000 | E18: =Volume!$C$26 | F18: =E18*$D18 | G18: =Volume!$D$26 | H18: =G18*$D18 | I18: =Volume!$E$26 | J18: =I18*$D18 | K18: Dipadatkan
A19: 2 | B19: Lantai rabat beton t = 8 cm + wiremesh M6 | C19: m² | D19: 185000 | E19: =Volume!$C$27 | F19: =E19*$D19 | G19: =Volume!$D$27 | H19: =G19*$D19 | I19: =Volume!$E$27 | J19: =I19*$D19 | K19: Beton K-175, kemiringan ke saluran
A20: 3 | B20: Keramik lantai 60×60 (dalam) | C20: m² | D20: 175000 | E20: =Volume!$C$28 | F20: =E20*$D20 | G20: =Volume!$D$28 | H20: =G20*$D20 | I20: =Volume!$E$28 | J20: =I20*$D20 | K20: Permukaan tidak licin
A21: 4 | B21: Floor hardener / acian lantai | C21: m² | D21: 55000 | E21: =Volume!$C$29 | F21: =E21*$D21 | G21: =Volume!$D$29 | H21: =G21*$D21 | I21: =Volume!$E$29 | J21: =I21*$D21 | K21: Teras & dalam bila tanpa keramik
A22: 5 | B22: Keramik dinding toilet h = 1,5 m | C22: m² | D22: 190000 | E22: =Volume!$C$30 | F22: =E22*$D22 | G22: =Volume!$D$30 | H22: =G22*$D22 | I22: =Volume!$E$30 | J22: =I22*$D22
A23: 6 | B23: Parkir sirtu dipadatkan t = 10 cm | C23: m² | D23: 45000 | E23: =Input!$C$29 | F23: =E23*$D23 | G23: =Input!$D$29 | H23: =G23*$D23 | I23: =Input!$E$29 | J23: =I23*$D23 | K23: Bisa diganti paving di tahap berikutnya
B24: Subtotal III | F24: =SUM(F18:F23) | H24: =SUM(H18:H23) | J24: =SUM(J18:J23)
A26: IV | B26: STRUKTUR BAJA (kolom & ring balk)
A27: 1 | B27: Kolom hollow galvanis 100×100×2,0 mm (batang 6 m) | C27: batang | D27: 520000 | E27: =Volume!$C$17 | F27: =E27*$D27 | G27: =Volume!$D$17 | H27: =G27*$D27 | I27: =Volume!$E$17 | J27: =I27*$D27 | K27: Kolom utama: jangan pakai kanal C baja ringan
A28: 2 | B28: Base plate + angkur + las per kolom | C28: titik | D28: 150000 | E28: =Volume!$C$17 | F28: =E28*$D28 | G28: =Volume!$D$17 | H28: =G28*$D28 | I28: =Volume!$E$17 | J28: =I28*$D28 | K28: Plat 8 mm, angkur 4 × M12
A29: 3 | B29: Ring balk hollow galvanis 50×100×2,0 mm (batang 6 m) | C29: batang | D29: 420000 | E29: =Volume!$C$19 | F29: =E29*$D29 | G29: =Volume!$D$19 | H29: =G29*$D29 | I29: =Volume!$E$19 | J29: =I29*$D29 | K29: Dudukan rangka atap & dinding
A30: 4 | B30: Upah pasang & las struktur | C30: m² | D30: 60000 | E30: =Volume!$C$13 | F30: =E30*$D30 | G30: =Volume!$D$13 | H30: =G30*$D30 | I30: =Volume!$E$13 | J30: =I30*$D30 | K30: Per m² proyeksi atap
A31: 5 | B31: Cat zinc chromate anti karat titik las | C31: ls | D31: 750000 | E31: =1 | F31: =E31*$D31 | G31: =1 | H31: =G31*$D31 | I31: =1 | J31: =I31*$D31
B32: Subtotal IV | F32: =SUM(F27:F31) | H32: =SUM(H27:H31) | J32: =SUM(J27:J31)
A34: V | B34: ATAP
A35: 1 | B35: Rangka atap baja ringan C75 + reng (borongan) | C35: m² | D35: 170000 | E35: =Volume!$C$14 | F35: =E35*$D35 | G35: =Volume!$D$14 | H35: =G35*$D35 | I35: =Volume!$E$14 | J35: =I35*$D35 | K35: Kuda-kuda jarak ≤ 1,2 m, minta gambar & garansi aplikator
A36: 2 | B36: Penutup atap spandek pasir 0,35 mm TCT | C36: m² | D36: 100000 | E36: =Volume!$C$14 | F36: =E36*$D36 | G36: =Volume!$D$14 | H36: =G36*$D36 | I36: =Volume!$E$14 | J36: =I36*$D36 | K36: Spandek pasir meredam bunyi hujan
A37: 3 | B37: Insulasi aluminium foil 2 sisi | C37: m² | D37: 20000 | E37: =Volume!$C$14 | F37: =E37*$D37 | G37: =Volume!$D$14 | H37: =G37*$D37 | I37: =Volume!$E$14 | J37: =I37*$D37 | K37: Meredam panas
A38: 4 | B38: Nok/bubungan | C38: m' | D38: 75000 | E38: =Volume!$C$20 | F38: =E38*$D38 | G38: =Volume!$D$20 | H38: =G38*$D38 | I38: =Volume!$E$20 | J38: =I38*$D38
A39: 5 | B39: Lisplang GRC 20 cm + cat | C39: m' | D39: 85000 | E39: =Volume!$C$21 | F39: =E39*$D39 | G39: =Volume!$D$21 | H39: =G39*$D39 | I39: =Volume!$E$21 | J39: =I39*$D39
A40: 6 | B40: Talang + pipa turun | C40: m' | D40: 120000 | E40: =Volume!$C$22 | F40: =E40*$D40 | G40: =Volume!$D$22 | H40: =G40*$D40 | I40: =Volume!$E$22 | J40: =I40*$D40
B41: Subtotal V | F41: =SUM(F35:F40) | H41: =SUM(H35:H40) | J41: =SUM(J35:J40)
A43: VI | B43: DINDING PARTISI
A44: 1 | B44: Dinding luar: rangka hollow 40×40 + GRC 8 mm luar & GRC 6 mm dalam | C44: m² | D44: 235000 | E44: =Volume!$C$33 | F44: =E44*$D44 | G44: =Volume!$D$33 | H44: =G44*$D44 | I44: =Volume!$E$33 | J44: =I44*$D44 | K44: Rangka jarak 60 cm, sambungan diberi kompon + kasa
A45: 2 | B45: Partisi dalam: rangka hollow 40×40 + GRC 6 mm dua sisi | C45: m² | D45: 200000 | E45: =Volume!$C$34 | F45: =E45*$D45 | G45: =Volume!$D$34 | H45: =G45*$D45 | I45: =Volume!$E$34 | J45: =I45*$D45
A46: 3 | B46: Dinding toilet bata ringan 7,5 cm + plester aci | C46: m² | D46: 230000 | E46: =Volume!$C$35 | F46: =E46*$D46 | G46: =Volume!$D$35 | H46: =G46*$D46 | I46: =Volume!$E$35 | J46: =I46*$D46 | K46: Area basah jangan pakai papan
...

Sheet Material
A1: DAFTAR BELANJA MATERIAL (perkiraan, sudah termasuk faktor sisa)
A2: Untuk mengecek penawaran tukang & belanja sendiri. Minta tukang memeriksa ulang sebelum memesan.
A4: Material | B4: Satuan | C4: Paket A · Lengkap | D4: Paket B · Hemat | E4: Paket C · Mulai Kecil | F4: Dasar hitung
A5: STRUKTUR & ATAP
A6: Hollow galvanis 100×100×2,0 mm, 6 m (kolom) | B6: batang | C6: =Volume!$C$17 | D6: =Volume!$D$17 | E6: =Volume!$E$17 | F6: 1 batang per kolom
A7: Hollow galvanis 50×100×2,0 mm, 6 m (ring balk) | B7: batang | C7: =Volume!$C$19 | D7: =Volume!$D$19 | E7: =Volume!$E$19
A8: Kanal C75 0,75 mm baja ringan, 6 m | B8: batang | C8: =ROUNDUP(Volume!$C$14*0.3*(1+Input!$C$40),0) | D8: =ROUNDUP(Volume!$D$14*0.3*(1+Input!$D$40),0) | E8: =ROUNDUP(Volume!$E$14*0.3*(1+Input!$E$40),0) | F8: ± 0,3 batang/m² atap
A9: Reng R32 0,45 mm, 6 m | B9: batang | C9: =ROUNDUP(Volume!$C$14*0.2*(1+Input!$C$40),0) | D9: =ROUNDUP(Volume!$D$14*0.2*(1+Input!$D$40),0) | E9: =ROUNDUP(Volume!$E$14*0.2*(1+Input!$E$40),0) | F9: reng jarak ± 1 m untuk spandek
A10: Spandek pasir 0,35 mm | B10: m² | C10: =ROUNDUP(Volume!$C$14*(1+Input!$C$40),0) | D10: =ROUNDUP(Volume!$D$14*(1+Input!$D$40),0) | E10: =ROUNDUP(Volume!$E$14*(1+Input!$E$40),0) | F10: pesan per panjang lembar sesuai sisi miring atap
A11: Aluminium foil 2 sisi (roll ± 75 m²) | B11: roll | C11: =ROUNDUP(Volume!$C$14*(1+Input!$C$40)/70,0) | D11: =ROUNDUP(Volume!$D$14*(1+Input!$D$40)/70,0) | E11: =ROUNDUP(Volume!$E$14*(1+Input!$E$40)/70,0)
A12: Baut roofing 12×20 | B12: pcs | C12: =ROUNDUP(Volume!$C$14*6,0) | D12: =ROUNDUP(Volume!$D$14*6,0) | E12: =ROUNDUP(Volume!$E$14*6,0) | F12: ± 6 per m²
A13: BETON & LANTAI
A14: Beton lantai rabat K-175 | B14: m³ | C14: =Volume!$C$27*0.08*(1+Input!$C$40) | D14: =Volume!$D$27*0.08*(1+Input!$D$40) | E14: =Volume!$E$27*0.08*(1+Input!$E$40) | F14: ready mix, atau ± 7 sak semen/m³ bila aduk di tempat
A15: Beton pondasi & sloof K-225 | B15: m³ | C15: =(Volume!$C$17*0.25+Volume!$C$25*0.03)*(1+Input!$C$40) | D15: =(Volume!$D$17*0.25+Volume!$D$25*0.03)*(1+Input!$D$40) | E15: =(Volume!$E$17*0.25+Volume!$E$25*0.03)*(1+Input!$E$40)
A16: Semen 50 kg (pondasi & sloof aduk di tempat) | B16: sak | C16: =ROUNDUP((Volume!$C$17*0.25+Volume!$C$25*0.03)*(1+Input!$C$40)*8,0) | D16: =ROUNDUP((Volume!$D$17*0.25+Volume!$D$25*0.03)*(1+Input!$D$40)*8,0) | E16: =ROUNDUP((Volume!$E$17*0.25+Volume!$E$25*0.03)*(1+Input!$E$40)*8,0) | F16: ± 8 sak/m³ K-225
A17: Besi ulir D10, 12 m | B17: batang | C17: =ROUNDUP((Volume!$C$25/12*4+Volume!$C$17*1.5)*(1+Input!$C$40),0) | D17: =ROUNDUP((Volume!$D$25/12*4+Volume!$D$17*1.5)*(1+Input!$D$40),0) | E17: =ROUNDUP((Volume!$E$25/12*4+Volume!$E$17*1.5)*(1+Input!$E$40),0)
A18: Wiremesh M6 2,1 × 5,4 m | B18: lembar | C18: =ROUNDUP(Volume!$C$27/10*(1+Input!$C$40),0) | D18: =ROUNDUP(Volume!$D$27/10*(1+Input!$D$40),0) | E18: =ROUNDUP(Volume!$E$27/10*(1+Input!$E$40),0)
A19: Pasir urug | B19: m³ | C19: =Volume!$C$26*(1+Input!$C$40) | D19: =Volume!$D$26*(1+Input!$D$40) | E19: =Volume!$E$26*(1+Input!$E$40)
A20: Keramik lantai 60×60 | B20: m² | C20: =Volume!$C$28*(1+Input!$C$40) | D20: =Volume!$D$28*(1+Input!$D$40) | E20: =Volume!$E$28*(1+Input!$E$40)
A21: Keramik dinding toilet | B21: m² | C21: =Volume!$C$30*(1+Input!$C$40) | D21: =Volume!$D$30*(1+Input!$D$40) | E21: =Volume!$E$30*(1+Input!$E$40)
A22: DINDING & FINISHING
A23: Papan GRC 8 mm 1,2 × 2,4 m | B23: lembar | C23: =ROUNDUP(Volume!$C$33/2.88*(1+Input!$C$40),0) | D23: =ROUNDUP(Volume!$D$33/2.88*(1+Input!$D$40),0) | E23: =ROUNDUP(Volume!$E$33/2.88*(1+Input!$E$40),0) | F23: sisi luar dinding luar
A24: Papan GRC 6 mm 1,2 × 2,4 m | B24: lembar | C24: =ROUNDUP((Volume!$C$33+2*Volume!$C$34)/2.88*(1+Input!$C$40),0) | D24: =ROUNDUP((Volume!$D$33+2*Volume!$D$34)/2.88*(1+Input!$D$40),0) | E24: =ROUNDUP((Volume!$E$33+2*Volume!$E$34)/2.88*(1+Input!$E$40),0) | F24: sisi dalam + partisi 2 sisi
A25: Hollow galvalum 40×40, 4 m (rangka partisi) | B25: batang | C25: =ROUNDUP((Volume!$C$33+Volume!$C$34)*2.2/4*(1+Input!$C$40),0) | D25: =ROUNDUP((Volume!$D$33+Volume!$D$34)*2.2/4*(1+Input!$D$40),0) | E25: =ROUNDUP((Volume!$E$33+Volume!$E$34)*2.2/4*(1+Input!$E$40),0) | F25: ± 2,2 m' per m² dinding
A26: Sekrup gypsum 6×25 | B26: pcs | C26: =ROUNDUP((Volume!$C$33*2+Volume!$C$34*2)*25,0) | D26: =ROUNDUP((Volume!$D$33*2+Volume!$D$34*2)*25,0) | E26: =ROUNDUP((Volume!$E$33*2+Volume!$E$34*2)*25,0) | F26: ± 25 per m² papan
A27: Kompon sambungan 20 kg | B27: sak | C27: =ROUNDUP((Volume!$C$33*2+Volume!$C$34*2)/25,0) | D27: =ROUNDUP((Volume!$D$33*2+Volume!$D$34*2)/25,0) | E27: =ROUNDUP((Volume!$E$33*2+Volume!$E$34*2)/25,0)
A28: Bata ringan 7,5 cm | B28: m² | C28: =Volume!$C$35*(1+Input!$C$40) | D28: =Volume!$D$35*(1+Input!$D$40) | E28: =Volume!$E$35*(1+Input!$E$40)
A29: Semen perekat bata ringan 40 kg | B29: sak | C29: =ROUNDUP(Volume!$C$35/7,0) | D29: =ROUNDUP(Volume!$D$35/7,0) | E29: =ROUNDUP(Volume!$E$35/7,0)
A30: Cat interior 25 kg | B30: pail | C30: =ROUNDUP(Volume!$C$37/120,0) | D30: =ROUNDUP(Volume!$D$37/120,0) | E30: =ROUNDUP(Volume!$E$37/120,0) | F30: 2 lapis
A31: Cat eksterior 20 L | B31: pail | C31: =ROUNDUP(Volume!$C$38/100,0) | D31: =ROUNDUP(Volume!$D$38/100,0) | E31: =ROUNDUP(Volume!$E$38/100,0) | F31: 2 lapis
A32: LISTRIK & AIR
A33: Kabel NYM 3 × 2,5 mm (roll 50 m) | B33: roll | C33: =ROUNDUP(Volume!$C$43*8/50,0) | D33: =ROUNDUP(Volume!$D$43*8/50,0) | E33: =ROUNDUP(Volume!$E$43*8/50,0) | F33: ± 8 m per titik
A34: Pipa PVC 1/2" air bersih, 4 m | B34: batang | C34: =Input!$C$33*2 | D34: =Input!$D$33*2 | E34: =Input!$E$33*2
A35: Pipa PVC 3" air kotor, 4 m | B35: batang | C35: =Input!$C$13*3+4 | D35: =Input!$D$13*3+4 | E35: =Input!$E$13*3+4

Sheet Jadwal
A1: JADWAL PELAKSANAAN & KURVA S
A2: Pilih paket (1 = A, 2 = B, 3 = C): | C2: 1 | D2: =CHOOSE($C$2,"Paket A · Lengkap","Paket B · Hemat","Paket C · Mulai Kecil")
A4: Pekerjaan | B4: Divisi RAB | C4: Bobot | D4: Minggu mulai | E4: Durasi (minggu) | F4: M1 | G4: M2 | H4: M3 | I4: M4 | J4: M5 | K4: M6 | L4: M7 | M4: M8 | N4: M9 | O4: M10
A5: Perizinan PBG & gambar kerja (sebelum mulai) | B5: XI | C5: =CHOOSE($C$2,RAB!$F$89,RAB!$H$89,RAB!$J$89)/CHOOSE($C$2,RAB!$F$91,RAB!$H$91,RAB!$J$91) | D5: 1 | E5: 1 | F5: =IF(AND(1>=$D5,1<$D5+$E5),$C5/$E5,0) | G5: =IF(AND(2>=$D5,2<$D5+$E5),$C5/$E5,0) | H5: =IF(AND(3>=$D5,3<$D5+$E5),$C5/$E5,0) | I5: =IF(AND(4>=$D5,4<$D5+$E5),$C5/$E5,0) | J5: =IF(AND(5>=$D5,5<$D5+$E5),$C5/$E5,0) | K5: =IF(AND(6>=$D5,6<$D5+$E5),$C5/$E5,0) | L5: =IF(AND(7>=$D5,7<$D5+$E5),$C5/$E5,0) | M5: =IF(AND(8>=$D5,8<$D5+$E5),$C5/$E5,0) | N5: =IF(AND(9>=$D5,9<$D5+$E5),$C5/$E5,0) | O5: =IF(AND(10>=$D5,10<$D5+$E5),$C5/$E5,0)
A6: Persiapan, pembersihan, bowplank | B6: I | C6: =CHOOSE($C$2,RAB!$F$10,RAB!$H$10,RAB!$J$10)/CHOOSE($C$2,RAB!$F$91,RAB!$H$91,RAB!$J$91) | D6: 1 | E6: 1 | F6: =IF(AND(1>=$D6,1<$D6+$E6),$C6/$E6,0) | G6: =IF(AND(2>=$D6,2<$D6+$E6),$C6/$E6,0) | H6: =IF(AND(3>=$D6,3<$D6+$E6),$C6/$E6,0) | I6: =IF(AND(4>=$D6,4<$D6+$E6),$C6/$E6,0) | J6: =IF(AND(5>=$D6,5<$D6+$E6),$C6/$E6,0) | K6: =IF(AND(6>=$D6,6<$D6+$E6),$C6/$E6,0) | L6: =IF(AND(7>=$D6,7<$D6+$E6),$C6/$E6,0) | M6: =IF(AND(8>=$D6,8<$D6+$E6),$C6/$E6,0) | N6: =IF(AND(9>=$D6,9<$D6+$E6),$C6/$E6,0) | O6: =IF(AND(10>=$D6,10<$D6+$E6),$C6/$E6,0)
A7: Pondasi umpak & sloof | B7: II | C7: =CHOOSE($C$2,RAB!$F$15,RAB!$H$15,RAB!$J$15)/CHOOSE($C$2,RAB!$F$91,RAB!$H$91,RAB!$J$91) | D7: 1 | E7: 2 | F7: =IF(AND(1>=$D7,1<$D7+$E7),$C7/$E7,0) | G7: =IF(AND(2>=$D7,2<$D7+$E7),$C7/$E7,0) | H7: =IF(AND(3>=$D7,3<$D7+$E7),$C7/$E7,0) | I7: =IF(AND(4>=$D7,4<$D7+$E7),$C7/$E7,0) | J7: =IF(AND(5>=$D7,5<$D7+$E7),$C7/$E7,0) | K7: =IF(AND(6>=$D7,6<$D7+$E7),$C7/$E7,0) | L7: =IF(AND(7>=$D7,7<$D7+$E7),$C7/$E7,0) | M7: =IF(AND(8>=$D7,8<$D7+$E7),$C7/$E7,0) | N7: =IF(AND(9>=$D7,9<$D7+$E7),$C7/$E7,0) | O7: =IF(AND(10>=$D7,10<$D7+$E7),$C7/$E7,0)
A8: Air & sanitasi (septic, sumur, pipa, sanitair) | B8: IX | C8: =CHOOSE($C$2,RAB!$F$74,RAB!$H$74,RAB!$J$74)/CHOOSE($C$2,RAB!$F$91,RAB!$H$91,RAB!$J$91) | D8: 2 | E8: 7 | F8: =IF(AND(1>=$D8,1<$D8+$E8),$C8/$E8,0) | G8: =IF(AND(2>=$D8,2<$D8+$E8),$C8/$E8,0) | H8: =IF(AND(3>=$D8,3<$D8+$E8),$C8/$E8,0) | I8: =IF(AND(4>=$D8,4<$D8+$E8),$C8/$E8,0) | J8: =IF(AND(5>=$D8,5<$D8+$E8),$C8/$E8,0) | K8: =IF(AND(6>=$D8,6<$D8+$E8),$C8/$E8,0) | L8: =IF(AND(7>=$D8,7<$D8+$E8),$C8/$E8,0) | M8: =IF(AND(8>=$D8,8<$D8+$E8),$C8/$E8,0) | N8: =IF(AND(9>=$D8,9<$D8+$E8),$C8/$E8,0) | O8: =IF(AND(10>=$D8,10<$D8+$E8),$C8/$E8,0)
A9: Struktur baja: kolom & ring balk | B9: IV | C9: =CHOOSE($C$2,RAB!$F$32,RAB!$H$32,RAB!$J$32)/CHOOSE($C$2,RAB!$F$91,RAB!$H$91,RAB!$J$91) | D9: 3 | E9: 2 | F9: =IF(AND(1>=$D9,1<$D9+$E9),$C9/$E9,0) | G9: =IF(AND(2>=$D9,2<$D9+$E9),$C9/$E9,0) | H9: =IF(AND(3>=$D9,3<$D9+$E9),$C9/$E9,0) | I9: =IF(AND(4>=$D9,4<$D9+$E9),$C9/$E9,0) | J9: =IF(AND(5>=$D9,5<$D9+$E9),$C9/$E9,0) | K9: =IF(AND(6>=$D9,6<$D9+$E9),$C9/$E9,0) | L9: =IF(AND(7>=$D9,7<$D9+$E9),$C9/$E9,0) | M9: =IF(AND(8>=$D9,8<$D9+$E9),$C9/$E9,0) | N9: =IF(AND(9>=$D9,9<$D9+$E9),$C9/$E9,0) | O9: =IF(AND(10>=$D9,10<$D9+$E9),$C9/$E9,0)
A10: Rangka & penutup atap | B10: V | C10: =CHOOSE($C$2,RAB!$F$41,RAB!$H$41,RAB!$J$41)/CHOOSE($C$2,RAB!$F$91,RAB!$H$91,RAB!$J$91) | D10: 4 | E10: 2 | F10: =IF(AND(1>=$D10,1<$D10+$E10),$C10/$E10,0) | G10: =IF(AND(2>=$D10,2<$D10+$E10),$C10/$E10,0) | H10: =IF(AND(3>=$D10,3<$D10+$E10),$C10/$E10,0) | I10: =IF(AND(4>=$D10,4<$D10+$E10),$C10/$E10,0) | J10: =IF(AND(5>=$D10,5<$D10+$E10),$C10/$E10,0) | K10: =IF(AND(6>=$D10,6<$D10+$E10),$C10/$E10,0) | L10: =IF(AND(7>=$D10,7<$D10+$E10),$C10/$E10,0) | M10: =IF(AND(8>=$D10,8<$D10+$E10),$C10/$E10,0) | N10: =IF(AND(9>=$D10,9<$D10+$E10),$C10/$E10,0) | O10: =IF(AND(10>=$D10,10<$D10+$E10),$C10/$E10,0)
A11: Lantai rabat, keramik, parkir | B11: III | C11: =CHOOSE($C$2,RAB!$F$24,RAB!$H$24,RAB!$J$24)/CHOOSE($C$2,RAB!$F$91,RAB!$H$91,RAB!$J$91) | D11: 5 | E11: 3 | F11: =IF(AND(1>=$D11,1<$D11+$E11),$C11/$E11,0) | G11: =IF(AND(2>=$D11,2<$D11+$E11),$C11/$E11,0) | H11: =IF(AND(3>=$D11,3<$D11+$E11),$C11/$E11,0) | I11: =IF(AND(4>=$D11,4<$D11+$E11),$C11/$E11,0) | J11: =IF(AND(5>=$D11,5<$D11+$E11),$C11/$E11,0) | K11: =IF(AND(6>=$D11,6<$D11+$E11),$C11/$E11,0) | L11: =IF(AND(7>=$D11,7<$D11+$E11),$C11/$E11,0) | M11: =IF(AND(8>=$D11,8<$D11+$E11),$C11/$E11,0) | N11: =IF(AND(9>=$D11,9<$D11+$E11),$C11/$E11,0) | O11: =IF(AND(10>=$D11,10<$D11+$E11),$C11/$E11,0)
A12: Dinding partisi, toilet, cat | B12: VI | C12: =CHOOSE($C$2,RAB!$F$51,RAB!$H$51,RAB!$J$51)/CHOOSE($C$2,RAB!$F$91,RAB!$H$91,RAB!$J$91) | D12: 5 | E12: 3 | F12: =IF(AND(1>=$D12,1<$D12+$E12),$C12/$E12,0) | G12: =IF(AND(2>=$D12,2<$D12+$E12),$C12/$E12,0) | H12: =IF(AND(3>=$D12,3<$D12+$E12),$C12/$E12,0) | I12: =IF(AND(4>=$D12,4<$D12+$E12),$C12/$E12,0) | J12: =IF(AND(5>=$D12,5<$D12+$E12),$C12/$E12,0) | K12: =IF(AND(6>=$D12,6<$D12+$E12),$C12/$E12,0) | L12: =IF(AND(7>=$D12,7<$D12+$E12),$C12/$E12,0) | M12: =IF(AND(8>=$D12,8<$D12+$E12),$C12/$E12,0) | N12: =IF(AND(9>=$D12,9<$D12+$E12),$C12/$E12,0) | O12: =IF(AND(10>=$D12,10<$D12+$E12),$C12/$E12,0)
A13: Listrik | B13: X | C13: =CHOOSE($C$2,RAB!$F$82,RAB!$H$82,RAB!$J$82)/CHOOSE($C$2,RAB!$F$91,RAB!$H$91,RAB!$J$91) | D13: 6 | E13: 3 | F13: =IF(AND(1>=$D13,1<$D13+$E13),$C13/$E13,0) | G13: =IF(AND(2>=$D13,2<$D13+$E13),$C13/$E13,0) | H13: =IF(AND(3>=$D13,3<$D13+$E13),$C13/$E13,0) | I13: =IF(AND(4>=$D13,4<$D13+$E13),$C13/$E13,0) | J13: =IF(AND(5>=$D13,5<$D13+$E13),$C13/$E13,0) | K13: =IF(AND(6>=$D13,6<$D13+$E13),$C13/$E13,0) | L13: =IF(AND(7>=$D13,7<$D13+$E13),$C13/$E13,0) | M13: =IF(AND(8>=$D13,8<$D13+$E13),$C13/$E13,0) | N13: =IF(AND(9>=$D13,9<$D13+$E13),$C13/$E13,0) | O13: =IF(AND(10>=$D13,10<$D13+$E13),$C13/$E13,0)
A14: Plafon | B14: VII | C14: =CHOOSE($C$2,RAB!$F$55,RAB!$H$55,RAB!$J$55)/CHOOSE($C$2,RAB!$F$91,RAB!$H$91,RAB!$J$91) | D14: 7 | E14: 2 | F14: =IF(AND(1>=$D14,1<$D14+$E14),$C14/$E14,0) | G14: =IF(AND(2>=$D14,2<$D14+$E14),$C14/$E14,0) | H14: =IF(AND(3>=$D14,3<$D14+$E14),$C14/$E14,0) | I14: =IF(AND(4>=$D14,4<$D14+$E14),$C14/$E14,0) | J14: =IF(AND(5>=$D14,5<$D14+$E14),$C14/$E14,0) | K14: =IF(AND(6>=$D14,6<$D14+$E14),$C14/$E14,0) | L14: =IF(AND(7>=$D14,7<$D14+$E14),$C14/$E14,0) | M14: =IF(AND(8>=$D14,8<$D14+$E14),$C14/$E14,0) | N14: =IF(AND(9>=$D14,9<$D14+$E14),$C14/$E14,0) | O14: =IF(AND(10>=$D14,10<$D14+$E14),$C14/$E14,0)
A15: Pintu, jendela, rolling door | B15: VIII | C15: =CHOOSE($C$2,RAB!$F$63,RAB!$H$63,RAB!$J$63)/CHOOSE($C$2,RAB!$F$91,RAB!$H$91,RAB!$J$91) | D15: 8 | E15: 2 | F15: =IF(AND(1>=$D15,1<$D15+$E15),$C15/$E15,0) | G15: =IF(AND(2>=$D15,2<$D15+$E15),$C15/$E15,0) | H15: =IF(AND(3>=$D15,3<$D15+$E15),$C15/$E15,0) | I15: =IF(AND(4>=$D15,4<$D15+$E15),$C15/$E15,0) | J15: =IF(AND(5>=$D15,5<$D15+$E15),$C15/$E15,0) | K15: =IF(AND(6>=$D15,6<$D15+$E15),$C15/$E15,0) | L15: =IF(AND(7>=$D15,7<$D15+$E15),$C15/$E15,0) | M15: =IF(AND(8>=$D15,8<$D15+$E15),$C15/$E15,0) | N15: =IF(AND(9>=$D15,9<$D15+$E15),$C15/$E15,0) | O15: =IF(AND(10>=$D15,10<$D15+$E15),$C15/$E15,0)
A16: Progres mingguan rencana | C16: =SUM(C5:C15) | F16: =SUM(F5:F15) | G16: =SUM(G5:G15) | H16: =SUM(H5:H15) | I16: =SUM(I5:I15) | J16: =SUM(J5:J15) | K16: =SUM(K5:K15) | L16: =SUM(L5:L15) | M16: =SUM(M5:M15) | ... O16: =SUM(O5:O15)
A17: Progres kumulatif rencana (kurva S) | F17: =F16 | G17: =F17+G16 | H17: =G17+H16 | I17: =H17+I16 | J17: =I17+J16 | K17: =J17+K16 | L17: =K17+L16 | M17: =L17+M16 | N17: =M17+N16 | O17: =N17+O16
A18: Progres kumulatif aktual (isi tiap minggu)
A20: Bobot = nilai divisi RAB ÷ total pekerjaan paket terpilih. Jadwal mengikuti cuaca: hindari mengecor & memasang atap saat hujan deras.

Sheet Checklist QC
A1: CHECKLIST PENGAWASAN LAPANGAN
A2: Cek setiap tahap sebelum lanjut ke tahap berikutnya. Foto setiap item dan simpan sebagai arsip.
A4: Tahap | B4: Item yang dicek | C4: Standar | D4: OK / Perbaiki | E4: Tanggal | F4: Catatan
A5: Persiapan | B5: Batas tanah & as bangunan | C5: Sesuai gambar & PBG, garis sempadan dari jalan dipatuhi
A6: Persiapan | B6: Elevasi lantai | C6: Lantai ± 20–30 cm di atas jalan/halaman agar tidak kebanjiran
A7: Pondasi | B7: Kedalaman galian umpak | C7: Mencapai tanah keras, min. 60–80 cm
A8: Pondasi | B8: Angkur kolom | C8: Tegak lurus, jarak sesuai base plate, dicek sebelum dicor
A9: Pondasi | B9: Pengecoran | C9: Tidak saat hujan, beton dipadatkan & disiram 7 hari
A10: Struktur | B10: Kolom | C10: Tegak (cek unting-unting/waterpass), las penuh, titik las dicat anti karat
A11: Struktur | B11: Ring balk | C11: Rata air, sambungan di atas kolom
A12: Atap | B12: Kuda-kuda baja ringan | C12: Jarak ≤ 1,2 m, terikat ke ring balk dengan dynabolt/bracket, ada ikatan angin
A13: Atap | B13: Penutup atap | C13: Overlap & baut roofing cukup, tidak bocor saat tes siram/hujan
A14: Atap | B14: Talang | C14: Miring ke pipa turun, tidak ada genangan
A15: Lantai | B15: Rabat beton | C15: Wiremesh terangkat (diganjal), miring ke saluran, tidak retak
A16: Dinding | B16: Rangka partisi | C16: Jarak rangka 60 cm, tegak, ada rangka ekstra di sekitar pintu/jendela & titik gantung
... A25: Finishing | B25: Keselamatan | C25: APAR terpasang, jalur keluar bebas, tidak ada kabel terbuka

Sheet Denah Tapak
A1: DENAH TAPAK 20 × 20 m (Paket A) · 1 kotak = 1 m
A2: Gambar ini contoh susunan dan tidak berubah otomatis. Arah jalan di bawah.
H4: DAPUR | M4: GUDANG | W4: Catatan susunan:
C5: SUMUR | R5: SEPTIC | W5: • Bangunan di tengah supaya ada jarak dari tetangga (aman kebakaran & cahaya).
M6: TOILET ×2 | W6: • Septic tank & sumur dibuat berjauhan (≥ 10 m).
W7: • Sisa lahan (± 270 m²) jadi area outdoor: bisa bertahap diberi kanopi/pergola.
B8: AREA OUTDOOR / TAMAN meja kayu, lampu gantung | H8: AREA DUDUK DALAM / RUANG REMBUK | P8: AREA OUTDOOR / TAMAN meja lesehan, pasar komunitas | W8: • Cek garis sempadan bangunan (GSB) dari jalan di Perda setempat.
H12: BAR & KASIR
H14: TERAS BERATAP 8 × 6 m meja nongkrong · area merokok
B20: PARKIR MOTOR · sirtu 80 m²
B24: JALAN
